2020-12-29 12:55:29,227 INFO: Microblog startup [in /home/liza/PycharmProjects/microblog2/app/__init__.py:54]
2020-12-29 13:13:19,812 INFO: Microblog startup [in /home/liza/PycharmProjects/microblog2/app/__init__.py:54]
2020-12-29 13:15:18,684 INFO: Microblog startup [in /home/liza/PycharmProjects/microblog2/app/__init__.py:54]
2020-12-29 13:16:24,347 INFO: Microblog startup [in /home/liza/PycharmProjects/microblog2/app/__init__.py:54]
2020-12-29 13:16:33,751 INFO: Microblog startup [in /home/liza/PycharmProjects/microblog2/app/__init__.py:54]
2020-12-29 13:19:02,700 INFO: Microblog startup [in /home/liza/PycharmProjects/microblog2/app/__init__.py:54]
2020-12-29 13:19:34,615 INFO: Microblog startup [in /home/liza/PycharmProjects/microblog2/app/__init__.py:54]
2020-12-29 13:20:02,686 INFO: Microblog startup [in /home/liza/PycharmProjects/microblog2/app/__init__.py:54]
2020-12-29 13:20:11,569 INFO: Microblog startup [in /home/liza/PycharmProjects/microblog2/app/__init__.py:54]
2020-12-29 13:20:28,849 INFO: Microblog startup [in /home/liza/PycharmProjects/microblog2/app/__init__.py:54]
2020-12-29 13:20:33,882 ERROR: Exception on /index [GET] [in /home/liza/PycharmProjects/microblog2/venv/lib/python3.8/site-packages/flask/app.py:1891]
Traceback (most recent call last):
  File "/home/liza/PycharmProjects/microblog2/venv/lib/python3.8/site-packages/flask/app.py", line 2447, in wsgi_app
    response = self.full_dispatch_request()
  File "/home/liza/PycharmProjects/microblog2/venv/lib/python3.8/site-packages/flask/app.py", line 1952, in full_dispatch_request
    rv = self.handle_user_exception(e)
  File "/home/liza/PycharmProjects/microblog2/venv/lib/python3.8/site-packages/flask/app.py", line 1821, in handle_user_exception
    reraise(exc_type, exc_value, tb)
  File "/home/liza/PycharmProjects/microblog2/venv/lib/python3.8/site-packages/flask/_compat.py", line 39, in reraise
    raise value
  File "/home/liza/PycharmProjects/microblog2/venv/lib/python3.8/site-packages/flask/app.py", line 1950, in full_dispatch_request
    rv = self.dispatch_request()
  File "/home/liza/PycharmProjects/microblog2/venv/lib/python3.8/site-packages/flask/app.py", line 1936, in dispatch_request
    return self.view_functions[rule.endpoint](**req.view_args)
  File "/home/liza/PycharmProjects/microblog2/venv/lib/python3.8/site-packages/flask_login/utils.py", line 271, in decorated_view
    return current_app.login_manager.unauthorized()
  File "/home/liza/PycharmProjects/microblog2/venv/lib/python3.8/site-packages/flask_login/login_manager.py", line 174, in unauthorized
    redirect_url = make_login_url(login_view, next_url=request.url)
  File "/home/liza/PycharmProjects/microblog2/venv/lib/python3.8/site-packages/flask_login/utils.py", line 120, in login_url
    base = expand_login_view(login_view)
  File "/home/liza/PycharmProjects/microblog2/venv/lib/python3.8/site-packages/flask_login/utils.py", line 97, in expand_login_view
    return url_for(login_view)
  File "/home/liza/PycharmProjects/microblog2/venv/lib/python3.8/site-packages/flask/helpers.py", line 370, in url_for
    return appctx.app.handle_url_build_error(error, endpoint, values)
  File "/home/liza/PycharmProjects/microblog2/venv/lib/python3.8/site-packages/flask/app.py", line 2216, in handle_url_build_error
    reraise(exc_type, exc_value, tb)
  File "/home/liza/PycharmProjects/microblog2/venv/lib/python3.8/site-packages/flask/_compat.py", line 39, in reraise
    raise value
  File "/home/liza/PycharmProjects/microblog2/venv/lib/python3.8/site-packages/flask/helpers.py", line 357, in url_for
    rv = url_adapter.build(
  File "/usr/local/lib/python3.8/dist-packages/werkzeug/routing.py", line 2179, in build
    raise BuildError(endpoint, values, method, self)
werkzeug.routing.BuildError: Could not build url for endpoint 'login'. Did you mean 'auth.login' instead?
2020-12-29 13:23:56,198 INFO: Microblog startup [in /home/liza/PycharmProjects/microblog2/app/__init__.py:54]
2020-12-29 13:23:58,053 ERROR: Exception on / [GET] [in /home/liza/PycharmProjects/microblog2/venv/lib/python3.8/site-packages/flask/app.py:1891]
Traceback (most recent call last):
  File "/home/liza/PycharmProjects/microblog2/venv/lib/python3.8/site-packages/flask/app.py", line 2447, in wsgi_app
    response = self.full_dispatch_request()
  File "/home/liza/PycharmProjects/microblog2/venv/lib/python3.8/site-packages/flask/app.py", line 1952, in full_dispatch_request
    rv = self.handle_user_exception(e)
  File "/home/liza/PycharmProjects/microblog2/venv/lib/python3.8/site-packages/flask/app.py", line 1821, in handle_user_exception
    reraise(exc_type, exc_value, tb)
  File "/home/liza/PycharmProjects/microblog2/venv/lib/python3.8/site-packages/flask/_compat.py", line 39, in reraise
    raise value
  File "/home/liza/PycharmProjects/microblog2/venv/lib/python3.8/site-packages/flask/app.py", line 1950, in full_dispatch_request
    rv = self.dispatch_request()
  File "/home/liza/PycharmProjects/microblog2/venv/lib/python3.8/site-packages/flask/app.py", line 1936, in dispatch_request
    return self.view_functions[rule.endpoint](**req.view_args)
  File "/home/liza/PycharmProjects/microblog2/venv/lib/python3.8/site-packages/flask_login/utils.py", line 271, in decorated_view
    return current_app.login_manager.unauthorized()
  File "/home/liza/PycharmProjects/microblog2/venv/lib/python3.8/site-packages/flask_login/login_manager.py", line 174, in unauthorized
    redirect_url = make_login_url(login_view, next_url=request.url)
  File "/home/liza/PycharmProjects/microblog2/venv/lib/python3.8/site-packages/flask_login/utils.py", line 120, in login_url
    base = expand_login_view(login_view)
  File "/home/liza/PycharmProjects/microblog2/venv/lib/python3.8/site-packages/flask_login/utils.py", line 97, in expand_login_view
    return url_for(login_view)
  File "/home/liza/PycharmProjects/microblog2/venv/lib/python3.8/site-packages/flask/helpers.py", line 370, in url_for
    return appctx.app.handle_url_build_error(error, endpoint, values)
  File "/home/liza/PycharmProjects/microblog2/venv/lib/python3.8/site-packages/flask/app.py", line 2216, in handle_url_build_error
    reraise(exc_type, exc_value, tb)
  File "/home/liza/PycharmProjects/microblog2/venv/lib/python3.8/site-packages/flask/_compat.py", line 39, in reraise
    raise value
  File "/home/liza/PycharmProjects/microblog2/venv/lib/python3.8/site-packages/flask/helpers.py", line 357, in url_for
    rv = url_adapter.build(
  File "/usr/local/lib/python3.8/dist-packages/werkzeug/routing.py", line 2179, in build
    raise BuildError(endpoint, values, method, self)
werkzeug.routing.BuildError: Could not build url for endpoint 'login'. Did you mean 'auth.login' instead?
2020-12-29 13:24:49,127 INFO: Microblog startup [in /home/liza/PycharmProjects/microblog2/app/__init__.py:54]
2020-12-29 13:24:50,984 ERROR: Exception on / [GET] [in /home/liza/PycharmProjects/microblog2/venv/lib/python3.8/site-packages/flask/app.py:1891]
Traceback (most recent call last):
  File "/home/liza/PycharmProjects/microblog2/venv/lib/python3.8/site-packages/flask/app.py", line 2447, in wsgi_app
    response = self.full_dispatch_request()
  File "/home/liza/PycharmProjects/microblog2/venv/lib/python3.8/site-packages/flask/app.py", line 1952, in full_dispatch_request
    rv = self.handle_user_exception(e)
  File "/home/liza/PycharmProjects/microblog2/venv/lib/python3.8/site-packages/flask/app.py", line 1821, in handle_user_exception
    reraise(exc_type, exc_value, tb)
  File "/home/liza/PycharmProjects/microblog2/venv/lib/python3.8/site-packages/flask/_compat.py", line 39, in reraise
    raise value
  File "/home/liza/PycharmProjects/microblog2/venv/lib/python3.8/site-packages/flask/app.py", line 1950, in full_dispatch_request
    rv = self.dispatch_request()
  File "/home/liza/PycharmProjects/microblog2/venv/lib/python3.8/site-packages/flask/app.py", line 1936, in dispatch_request
    return self.view_functions[rule.endpoint](**req.view_args)
  File "/home/liza/PycharmProjects/microblog2/venv/lib/python3.8/site-packages/flask_login/utils.py", line 271, in decorated_view
    return current_app.login_manager.unauthorized()
  File "/home/liza/PycharmProjects/microblog2/venv/lib/python3.8/site-packages/flask_login/login_manager.py", line 174, in unauthorized
    redirect_url = make_login_url(login_view, next_url=request.url)
  File "/home/liza/PycharmProjects/microblog2/venv/lib/python3.8/site-packages/flask_login/utils.py", line 120, in login_url
    base = expand_login_view(login_view)
  File "/home/liza/PycharmProjects/microblog2/venv/lib/python3.8/site-packages/flask_login/utils.py", line 97, in expand_login_view
    return url_for(login_view)
  File "/home/liza/PycharmProjects/microblog2/venv/lib/python3.8/site-packages/flask/helpers.py", line 370, in url_for
    return appctx.app.handle_url_build_error(error, endpoint, values)
  File "/home/liza/PycharmProjects/microblog2/venv/lib/python3.8/site-packages/flask/app.py", line 2216, in handle_url_build_error
    reraise(exc_type, exc_value, tb)
  File "/home/liza/PycharmProjects/microblog2/venv/lib/python3.8/site-packages/flask/_compat.py", line 39, in reraise
    raise value
  File "/home/liza/PycharmProjects/microblog2/venv/lib/python3.8/site-packages/flask/helpers.py", line 357, in url_for
    rv = url_adapter.build(
  File "/usr/local/lib/python3.8/dist-packages/werkzeug/routing.py", line 2179, in build
    raise BuildError(endpoint, values, method, self)
werkzeug.routing.BuildError: Could not build url for endpoint 'login'. Did you mean 'auth.login' instead?
2020-12-29 13:25:33,776 INFO: Microblog startup [in /home/liza/PycharmProjects/microblog2/app/__init__.py:54]
